Workbook
Name Slicer_Marital_Status: #N/A
Name Slicer_Gender: #N/A
Name Slicer_Region: #N/A
Name Slicer_Purchased_Bike: #N/A

Sheet bike_buyers
A1: ID | B1: Marital Status | C1: Gender | D1: Income | E1: Children | F1: Education | G1: Occupation | H1: Home Owner | I1: Cars | J1: Commute Distance | K1: Region | L1: Age | M1: Purchased Bike
A2: 12496 | B2: M | C2: F | D2: 40000 | E2: 1 | F2: Bachelors | G2: Skilled Manual | H2: Yes | I2: 0 | J2: 0-1 Miles | K2: Europe | L2: 42 | M2: No
A3: 24107 | B3: M | C3: M | D3: 30000 | E3: 3 | F3: Partial College | G3: Clerical | H3: Yes | I3: 1 | J3: 0-1 Miles | K3: Europe | L3: 43 | M3: No
A4: 14177 | B4: M | C4: M | D4: 80000 | E4: 5 | F4: Partial College | G4: Professional | H4: No | I4: 2 | J4: 2-5 Miles | K4: Europe | L4: 60 | M4: No
A5: 24381 | B5: S | C5: M | D5: 70000 | E5: 0 | F5: Bachelors | G5: Professional | H5: Yes | I5: 1 | J5: 5-10 Miles | K5: Pacific | L5: 41 | M5: Yes
A6: 25597 | B6: S | C6: M | D6: 30000 | E6: 0 | F6: Bachelors | G6: Clerical | H6: No | I6: 0 | J6: 0-1 Miles | K6: Europe | L6: 36 | M6: Yes
A7: 13507 | B7: M | C7: F | D7: 10000 | E7: 2 | F7: Partial College | G7: Manual | H7: Yes | I7: 0 | J7: 1-2 Miles | K7: Europe | L7: 50 | M7: No
A8: 27974 | B8: S | C8: M | D8: 160000 | E8: 2 | F8: High School | G8: Management | H8: Yes | I8: 4 | J8: 0-1 Miles | K8: Pacific | L8: 33 | M8: Yes
A9: 19364 | B9: M | C9: M | D9: 40000 | E9: 1 | F9: Bachelors | G9: Skilled Manual | H9: Yes | I9: 0 | J9: 0-1 Miles | K9: Europe | L9: 43 | M9: Yes
A10: 22155 | B10: M | C10: M | D10: 20000 | E10: 2 | F10: Partial High School | G10: Clerical | H10: Yes | I10: 2 | J10: 5-10 Miles | K10: Pacific | L10: 58 | M10: No
A11: 19280 | B11: M | C11: M | D11: 120000 | E11: 2 | F11: Partial College | G11: Manual | H11: Yes | I11: 1 | J11: 0-1 Miles | K11: Europe | L11: 40 | M11: Yes
A12: 22173 | B12: M | C12: F | D12: 30000 | E12: 3 | F12: High School | G12: Skilled Manual | H12: No | I12: 2 | J12: 1-2 Miles | K12: Pacific | L12: 54 | M12: Yes
A13: 12697 | B13: S | C13: F | D13: 90000 | E13: 0 | F13: Bachelors | G13: Professional | H13: No | I13: 4 | J13: 10+ Miles | K13: Pacific | L13: 36 | M13: No
... A1027: 18484 | B1027: S | C1027: M | D1027: 80000 | E1027: 2 | F1027: High School | G1027: Skilled Manual | H1027: No | I1027: 2 | J1027: 1-2 Miles | K1027: Pacific | L1027: 50 | M1027: Yes

Sheet Dashboard

Sheet Pivot Table 
B4: Purchased Bike | C4: No. | D4: Percent
B5: Non-Buyers | C5: 519 | D5: 0.519
B6: Buyers | C6: 481 | D6: 0.481
B7: Grand Total | C7: 1000 | D7: 1
B14: . | C14: Average Age
B15: Bike Buyers | C15: =AVERAGEIF('Working Sheet'!O2:O1001,"Yes",'Working Sheet'!M2:M1001) -> 42.906445
B16: Non-Buyers | C16: =AVERAGEIF('Working Sheet'!O3:O1002,"No",'Working Sheet'!M3:M1002) -> 45.333977
B18: Count of Purchased Bike | C18: Purchased Bike | G18: Count of Purchased Bike | H18: Purchased Bike
B19: Age Brackets | C19: No | D19: Yes | E19: Grand Total | G19: Gender | H19: No | I19: Yes | J19: Grand Total
B20: Middle-Aged | C20: 0.37 | D20: 0.405 | E20: 0.775 | G20: Female | H20: 0.25 | I20: 0.239 | J20: 0.489
B21: Seniors | C21: 0.078 | D21: 0.037 | E21: 0.115 | G21: Male | H21: 0.269 | I21: 0.242 | J21: 0.511
B22: Young Adults | C22: 0.071 | D22: 0.039 | E22: 0.11 | G22: Grand Total | H22: 0.519 | I22: 0.481 | J22: 1
B23: Grand Total | C23: 0.519 | D23: 0.481 | E23: 1
B27: Metrics | C27: Buyers | D27: Non-buyers
B28: Customer Count | C28: =COUNTIF(bike_buyers!M2:M1001,"Yes") -> 481 | D28: =COUNTIF(bike_buyers!M2:M1001,"No") -> 519
B30: Average Age | C30: =AVERAGEIFS(bike_buyers!L2:L1001,bike_buyers!M2:M1001,"Yes") -> 42.906445 | D30: =AVERAGEIFS(bike_buyers!L2:L1001,bike_buyers!M2:M1001,"No") -> 45.327553
B32: Average Income | C32: =AVERAGEIFS(bike_buyers!D2:D1001,bike_buyers!M2:M1001,"Yes") -> 57962.578 | D32: =AVERAGEIFS(bike_buyers!D2:D1001,bike_buyers!M2:M1001,"No") -> 54874.759
B34: Average no. of Cars | C34: =AVERAGEIFS(bike_buyers!I2:I1001,bike_buyers!M2:M1001,"Yes") -> 1.2120582 | D34: =AVERAGEIFS(bike_buyers!I2:I1001,bike_buyers!M2:M1001,"No") -> 1.655106
B36: Average no. of Children | C36: =AVERAGEIFS(bike_buyers!E2:E1001,bike_buyers!M2:M1001,"Yes") -> 1.6964657 | D36: =AVERAGEIFS(bike_buyers!E2:E1001,bike_buyers!M2:M1001,"No") -> 2.0847784
B45: Combined Analysis
B46: Purchased Bike | C46: (ALL)
B48: Count of Purchased Bike | C48: Column Labels
B49: Row Labels | C49: Middle-Aged | D49: Seniors | E49: Young Adults | F49: Grand Total
B50: 0-1 Miles | C50: 0.302 | D50: 0.025 | E50: 0.039 | F50: 0.366
B51: 1-2 Miles | C51: 0.138 | D51: 0.015 | E51: 0.016 | F51: 0.169
B52: 2-5 Miles | C52: 0.134 | D52: 0.013 | E52: 0.015 | F52: 0.162
B53: 5-10 Miles | C53: 0.123 | D53: 0.032 | E53: 0.037 | F53: 0.192
B54: More than 10 miles | C54: 0.078 | D54: 0.03 | E54: 0.003 | F54: 0.111
B55: Grand Total | C55: 0.775 | D55: 0.115 | E55: 0.11 | F55: 1
B57: Purchased Bike | C57: (ALL)
B59: Count of Purchased Bike | C59: Commute Distance
B60: No. of Cars | C60: 0-1 Miles | D60: 1-2 Miles | E60: 2-5 Miles | F60: 5-10 Miles | G60: More than 10 miles | H60: Grand Total
B61: 0 | C61: 0.168 | D61: 0.031 | E61: 0.036 | F61: 0.008 | G61: 0.004 | H61: 0.247
B62: 1 | C62: 0.085 | D62: 0.048 | E62: 0.072 | F62: 0.049 | G62: 0.013 | H62: 0.267
B63: 2 | C63: 0.079 | D63: 0.075 | E63: 0.038 | F63: 0.107 | G63: 0.043 | H63: 0.342
B64: 3 | C64: 0.018 | D64: 0.008 | E64: 0.008 | F64: 0.019 | G64: 0.032 | H64: 0.085
B65: 4 | C65: 0.016 | D65: 0.007 | E65: 0.008 | F65: 0.009 | G65: 0.019 | H65: 0.059
B66: Grand Total | C66: 0.366 | D66: 0.169 | E66: 0.162 | F66: 0.192 | G66: 0.111 | H66: 1
B68: Purchased Bike | C68: (ALL)
B70: Count of Purchased Bike | C70: Children
...

Sheet Working Sheet
A1: ID | B1: Marital Status | C1: Gender | D1: Income | E1: Income Bracket | F1: Children | G1: Education | H1: Occupation | I1: Home Owner | J1: Cars | K1: Commute Distance | L1: Region | M1: Age | N1: Age Brackets | O1: Purchased Bike
A2: 12496 | B2: Married | C2: Female | D2: 40000 | E2: {=_xlfn.IFS(D2<40000,"Low Income",D2<=80000,"Moderate Income",D2>80000,"High Income")} -> Moderate Income | F2: 1 | G2: Bachelors | H2: Skilled Manual | I2: Yes | J2: 0 | K2: 0-1 Miles | L2: Europe | M2: 42 | N2: =IF(M2>=60,"Seniors",IF(M2>30,"Middle-Aged",IF(M2<=30,"Young Adults"))) -> Middle-Aged | O2: No
A3: 24107 | B3: Married | C3: Male | D3: 30000 | E3: {=_xlfn.IFS(D3<40000,"Low Income",D3<=80000,"Moderate Income",D3>80000,"High Income")} -> Low Income | F3: 3 | G3: Partial College | H3: Clerical | I3: Yes | J3: 1 | K3: 0-1 Miles | L3: Europe | M3: 43 | N3: =IF(M3>=60,"Seniors",IF(M3>30,"Middle-Aged",IF(M3<=30,"Young Adults"))) -> Middle-Aged | O3: No
A4: 14177 | B4: Married | C4: Male | D4: 80000 | E4: {=_xlfn.IFS(D4<40000,"Low Income",D4<=80000,"Moderate Income",D4>80000,"High Income")} -> Moderate Income | F4: 5 | G4: Partial College | H4: Professional | I4: No | J4: 2 | K4: 2-5 Miles | L4: Europe | M4: 60 | N4: =IF(M4>=60,"Seniors",IF(M4>30,"Middle-Aged",IF(M4<=30,"Young Adults"))) -> Seniors | O4: No
A5: 24381 | B5: Single | C5: Male | D5: 70000 | E5: {=_xlfn.IFS(D5<40000,"Low Income",D5<=80000,"Moderate Income",D5>80000,"High Income")} -> Moderate Income | F5: 0 | G5: Bachelors | H5: Professional | I5: Yes | J5: 1 | K5: 5-10 Miles | L5: Pacific | M5: 41 | N5: =IF(M5>=60,"Seniors",IF(M5>30,"Middle-Aged",IF(M5<=30,"Young Adults"))) -> Middle-Aged | O5: Yes
A6: 25597 | B6: Single | C6: Male | D6: 30000 | E6: {=_xlfn.IFS(D6<40000,"Low Income",D6<=80000,"Moderate Income",D6>80000,"High Income")} -> Low Income | F6: 0 | G6: Bachelors | H6: Clerical | I6: No | J6: 0 | K6: 0-1 Miles | L6: Europe | M6: 36 | N6: =IF(M6>=60,"Seniors",IF(M6>30,"Middle-Aged",IF(M6<=30,"Young Adults"))) -> Middle-Aged | O6: Yes
A7: 13507 | B7: Married | C7: Female | D7: 10000 | E7: {=_xlfn.IFS(D7<40000,"Low Income",D7<=80000,"Moderate Income",D7>80000,"High Income")} -> Low Income | F7: 2 | G7: Partial College | H7: Manual | I7: Yes | J7: 0 | K7: 1-2 Miles | L7: Europe | M7: 50 | N7: =IF(M7>=60,"Seniors",IF(M7>30,"Middle-Aged",IF(M7<=30,"Young Adults"))) -> Middle-Aged | O7: No
A8: 27974 | B8: Single | C8: Male | D8: 160000 | E8: {=_xlfn.IFS(D8<40000,"Low Income",D8<=80000,"Moderate Income",D8>80000,"High Income")} -> High Income | F8: 2 | G8: High School | H8: Management | I8: Yes | J8: 4 | K8: 0-1 Miles | L8: Pacific | M8: 33 | N8: =IF(M8>=60,"Seniors",IF(M8>30,"Middle-Aged",IF(M8<=30,"Young Adults"))) -> Middle-Aged | O8: Yes
A9: 19364 | B9: Married | C9: Male | D9: 40000 | E9: {=_xlfn.IFS(D9<40000,"Low Income",D9<=80000,"Moderate Income",D9>80000,"High Income")} -> Moderate Income | F9: 1 | G9: Bachelors | H9: Skilled Manual | I9: Yes | J9: 0 | K9: 0-1 Miles | L9: Europe | M9: 43 | N9: =IF(M9>=60,"Seniors",IF(M9>30,"Middle-Aged",IF(M9<=30,"Young Adults"))) -> Middle-Aged | O9: Yes
A10: 22155 | B10: Married | C10: Male | D10: 20000 | E10: {=_xlfn.IFS(D10<40000,"Low Income",D10<=80000,"Moderate Income",D10>80000,"High Income")} -> Low Income | F10: 2 | G10: Partial High School | H10: Clerical | I10: Yes | J10: 2 | K10: 5-10 Miles | L10: Pacific | M10: 58 | N10: =IF(M10>=60,"Seniors",IF(M10>30,"Middle-Aged",IF(M10<=30,"Young Adults"))) -> Middle-Aged | O10: No
A11: 19280 | B11: Married | C11: Male | D11: 120000 | E11: {=_xlfn.IFS(D11<40000,"Low Income",D11<=80000,"Moderate Income",D11>80000,"High Income")} -> High Income | F11: 2 | G11: Partial College | H11: Manual | I11: Yes | J11: 1 | K11: 0-1 Miles | L11: Europe | M11: 40 | N11: =IF(M11>=60,"Seniors",IF(M11>30,"Middle-Aged",IF(M11<=30,"Young Adults"))) -> Middle-Aged | O11: Yes
A12: 22173 | B12: Married | C12: Female | D12: 30000 | E12: {=_xlfn.IFS(D12<40000,"Low Income",D12<=80000,"Moderate Income",D12>80000,"High Income")} -> Low Income | F12: 3 | G12: High School | H12: Skilled Manual | I12: No | J12: 2 | K12: 1-2 Miles | L12: Pacific | M12: 54 | N12: =IF(M12>=60,"Seniors",IF(M12>30,"Middle-Aged",IF(M12<=30,"Young Adults"))) -> Middle-Aged | O12: Yes
A13: 12697 | B13: Single | C13: Female | D13: 90000 | E13: {=_xlfn.IFS(D13<40000,"Low Income",D13<=80000,"Moderate Income",D13>80000,"High Income")} -> High Income | F13: 0 | G13: Bachelors | H13: Professional | I13: No | J13: 4 | K13: More than 10 miles | L13: Pacific | M13: 36 | N13: =IF(M13>=60,"Seniors",IF(M13>30,"Middle-Aged",IF(M13<=30,"Young Adults"))) -> Middle-Aged | O13: No
... A1001: 12121 | B1001: Single | C1001: Male | D1001: 60000 | E1001: {=_xlfn.IFS(D1001<40000,"Low Income",D1001<=80000,"Moderate Income",D1001>80000,"High Income")} -> Moderate Income | F1001: 3 | G1001: High School | H1001: Professional | I1001: Yes | J1001: 2 | K1001: More than 10 miles | L1001: North America | M1001: 53 | N1001: =IF(M1001>=60,"Seniors",IF(M1001>30,"Middle-Aged",IF(M1001<=30,"Young Adults"))) -> Middle-Aged | O1001: Yes
